Workbook
Name _Hlk153478266: Лист2!$K$19

Sheet Лист1
A1: V(ов) л | B1: =4*0.3*20*60*24*365 -> 12614400 | D1: Н(рег) | E1: 20 | G1: Р(о) кг/м3 | H1: 1.429 | J1: S(др ф) | K1: 72 | M1: m(прод о др ф), т/м2 | N1: =12.5/10000 -> 0.00125 | P1: m(погл co2 др ф), т/м2 | Q1: =16.5/10000 -> 0.00165
A2: V(ов) м3 | B2: =B1/1000 -> 12614.4 | D2: К(кв) | E2: 20.8 | G2: P(co2) кг/м3 | H2: 1.977 | J2: S(топ) | K2: 51 | M2: m(прод о топ), т/м2 | N2: =34.9/10000 -> 0.00349 | P2: m(погл co2 топ), т/м2 | Q2: =46.2/10000 -> 0.00462
D3: К(выд о) | E3: 16.4 | J3: S(об дер) | K3: =SUM(K1:K2) -> 123 | M3: m(прод о газ), т/м2 | N3: =7.5/10000 -> 0.00075 | P3: m(погл co2 газ), т/м2 | Q3: =10/10000 -> 0.001
A4: V(чо) | B4: =(B2*20.8)/100 -> 2623.7952 | D4: К(укв) | E4: 0.038 | J4: S(куст) | K4: 25
A5: V(чо н рег) | B5: =B4*E1 -> 52475.904 | D5: К(выд co2) | E5: 4 | J5: S(газ) | K5: 53
D6: N(дер) | E6: 30
A7: М(чо н рег) кг | B7: =B5*H1 -> 74988.067
A8: М(чо н рег) т | B8: =B7/1000 -> 74.988067 | C8: оптимальное количество для стабильной работы организма
A10: К(ов) | B10: =E2-E3 -> 4.4
A12: V(ож 1ч) | B12: =B2*E2/100 -> 2623.7952
A13: V(ож н рег) | B13: =B12*E1 -> 52475.904
A15: М(ож н рег), т | B15: =B13*H1/1000 -> 74.988067 | C15: Минимальное количество кислорода | F15: =B15/20 -> 3.7494033 | G15: Минимальное количество кислорода на 1 человека
A17: V(со2 в) | B17: =B2*E4/100 -> 4.793472
A18: V(со2 н рег) | B18: =B17*E1 -> 95.86944
A20: M(со2 н рег), т | B20: =B18*H2/1000 -> 0.18953388 | C20: Этот результат зафиксировать в выводе, как физиологически комфортную концентрацию СО2.
A22: K(ов co2) | B22: =E5-E4 -> 3.962
A24: V(co2ж1ч) | B24: =B2*B22/100 -> 499.78253
A25: V(co2ж н рег) | B25: =B24*E1 -> 9995.6506
A27: M(co2ж н рег), т | B27: =B25*H2/1000 -> 19.761401 | C27: Это количество углекислого газа, создаваемого в процессе жизнедеятельности людей - физиологический вклад населения. Этот результат зафиксировать в выводе.
A29: M(выд о др ф) | B29: =N1*$K$1 -> 0.09 | D29: M(погл co2 др ф) | E29: =Q1*$K$1 -> 0.1188
A30: M(выд о топ) | B30: =N2*$K$1 -> 0.25128 | D30: M(погл co2 топ) | E30: =Q2*$K$1 -> 0.33264
A31: M(выд о газ) | B31: =N3*$K$1 -> 0.054 | D31: M(погл co2 газ) | E31: =Q3*$K$1 -> 0.072
A32: M(выд о) | B32: =SUM(B29:B31) -> 0.39528 | D32: M(погл со2) | E32: =SUM(E29:E31) -> 0.52344
A34: O(o) | B34: =(B32/B15)*100 -> 0.52712387
A36: Б(о2) | B36: =(B32/B8)*100 -> 0.52712387
A37: Б(co2) | B37: =E32/B20 -> 2.7617226
A39: M(нехв о) | B39: =B15-B32 -> 74.592787
A40: S(зел нас треб доп) | B40: =B39/B32 -> 188.70873
A42: S(д1) | B42: =K3/E6 -> 4.1
A43: К(д) | B43: =B46/B42 -> 95.05091
A45: S(зел нас факт) | B45: =K3+K4+K5 -> 201 | D45: S(зел нас факт/чел) | E45: =B45/E1 -> 10.05
A46: S(зел нас треб) | B46: =B45+B40 -> 389.70873 | D46: S(зел нас треб/чел) | E46: =B46/E1 -> 19.485437
H59: Вывод | I59: Баланс кислорода слишком мал. Необходимо большее количество зелёных насаждений для выработки кислорода и поглощения углекислого газа

Sheet Лист2
A1: Исходные данные | G1: Тип автотранспорта | H1: Число автомобилей на территории, ед (Nа) | I1: Общий путь, пройденный общим количеством автомашин, км (L) | K1: Тип автотранспорта | L1: Норма расхода, | M1: Удельный расход | O1: Тип автотранспорта | P1: Q
A2: QОкг топл | B2: 1.338 | C2: кг | G2: Легковой (Б) | H2: =B4 -> 5 | I2: =B8 -> 75000 | L2: л /100 км (Q) | M2: топлива, л /км (q) | P2: Бензин Qб | Q2: Дизтопливо Qдт
A3: Население составляет Н | B3: 20 | C3: чел | G3: Грузовой (Б) | K3: Легковой (Б) | L3: 8 – 14 | M3: =11/100 -> 0.11 | O3: Легковой (Б) | P3: =B10 -> 8250 | Q3: ─
A4: NОМ | B4: 5 | C4: легковые | G4: Автобусы (Б) | K4: Грузовой (Б) | L4: 26 – 28 | O4: Автобусы (Б) | Q4: ─
A5: Lср | B5: 15000 | C5: км/год | G5: Легковой (ДТ) | K5: Автобусы (Б) | L5: 30 – 32 | O5: Грузовой (Б) | Q5: ─
G6: Автобусы (ДТ) | K6: Грузовой (ДТ) | L6: 22 ─ 24 | O6: Легковой (ДТ) | P6: ─
A7: КМ 1 ч | B7: =B4/B3 -> 0.25 | C7: ед/чел | G7: Грузовой (ДТ) | K7: Автобусы (ДТ) | L7: 24 – 26 | O7: Автобусы (ДТ) | P7: ─
A8: Lобщ | B8: =B4*B5 -> 75000 | C8: км/год | K8: Газель (ДТ) | L8: 6 ─ 8 | O8: Грузовой (ДТ) | P8: ─
O9: Всего | P9: =SUM(P3:P8) -> 8250
A10: Qб | B10: =B8*M3 -> 8250 | C10: л | G10: Вид топлива | H10: Значение коэффициентов (Кввт), кг/т, (г/кг)
A11: P | B11: 0.75 | C11: кг/л | H11: СО | I11: SO2 | J11: NO2 | K11: Pb | L11: CnHn | M11: сажа
G12: Бензин | H12: 395 | I12: 1.6 | J12: 20 | K12: 0.7 | L12: 34 | M12: 2
A13: Мб | B13: =B10*B11 -> 6187.5 | C13: кг | G13: Дизтопливо | H13: 9 | I13: 6 | J13: 33 | K13: — | L13: 20 | M13: 16
A14: Мобщ | B14: =B13 -> 6187.5 | C14: кг
G15: Тип автотранспорта | H15: Проехало автомобилей в течение 20 мин, ед | I15: Проехало автомобилей в течение 1 ч, ед | J15: Общий путь, пройденный общим количеством автомашин за 1 ч, км (L)
A16: Ro | B16: =B14*B2 -> 8278.875 | C16: кг | D16: на 1 человека, т | E16: на 1 машину, т | G16: Легковой (Б) | H16: =B4 -> 5 | I16: =H16*3 -> 15 | J16: =B21*I16*2 -> 6
A17: Ro | B17: =B16/1000 -> 8.278875 | C17: т | D17: 3.7494033 | E17: =B17/5 -> 1.655775 | G17: Грузовой (Б)
G18: Автобусы (Б)
A19: Lобщ | B19: =B20*B21 -> 1 | C19: км | G19: Легковой (ДТ)
A20: Na | B20: =B4 -> 5 | G20: Грузовой (ДТ)
A21: Lуч | B21: =0.2 -> 0.2 | C21: км | G21: Автобусы (ДТ)
A23: m ввп/час | B23: =H34 -> 0 | G23: Вид | H23: Удельные пробеговые выбросы, мг/м (г/км)
G24: автотранспорта | H24: CO | I24: CnHn | J24: NO2 | K24: C | L24: SO2 | M24: Pb | N24: SO3 | O24: С20Н12 | P24: NO
A25: Vу | B25: =B26*B27*B28 -> 3.5e-06 | C25: км3 | D25: =D26*D27*D28 -> 3500 | E25: м3 | G25: Легковой (Б) | H25: 19.8 | I25: 2.3 | J25: 0.28 | K25: - | L25: 0.07 | M25: 0.035 | O25: =0.18*10^-6 -> 1.8e-07 | P25: 0.043
A26: Lуч | B26: =B21 -> 0.2 | D26: =B26*1000 -> 200 | E26: м | G26: Автобусы, | H26: 37.3 | I26: 6.9 | J26: 0.8 | K26: - | L26: 0.19 | M26: 0.043 | N26: 0.85 | O26: 0,73х10-6 | P26: 0.234
A27: Ш | B27: =10/1000 -> 0.01 | C27: км | D27: =B27*1000 -> 10 | E27: м | G27: Грузовые (Б)
A28: Н | B28: =1.75/1000 -> 0.00175 | C28: км | D28: =B28*1000 -> 1.75 | E28: м | G28: Легковой, «Газели» (ДТ) | H28: 28.5 | I28: 3.5 | J28: 0.6 | K28: - | L28: 0.11 | M28: 0.054 | N28: 0.88 | O28: 0,6х10-6 | P28: 0.832
G29: Автобусы, Грузовые (ДТ) | H29: 6.2 | I29: 1.1 | J29: 3.5 | K29: 0.3 | L29: 0.56 | M29: - | O29: 0,2х10-6 | P29: 4.72
F31: Вредное вещество | H31: Масса вредного вещества при сгорании топлива (m ввт), г | I31: Масса вредного вещества по пробеговому выбросу (m ввп), г | J31: Общая масса вредного вещества (m вв),
A32: ППР О 1ГА ЛМ | B32: 16.7 | C32: Т/га | J32: Годовая | K32: Суточная
A33: SНЛМА | B33: =B17/B32 -> 0.49574102 | C33: га | F33: CO | G33: Б | H33: =B13*H12 -> 2444062.5 | I33: =B19*H25*24*365 -> 173448 | J33: =SUM(H33:I33) -> 2617510.5 | K33: =J33/365 -> 7171.2616
A34: S зел нас треб | B34: 0.038970873 | C34: га | G34: ДТ
A35: SОБЩ | B35: =B34+B33 -> 0.53471189 | C35: га | F35: SO2 | G35: Б | H35: =B13*I12 -> 9900 | I35: =B19*L25*24*365 -> 613.2 | J35: =SUM(H35:I35) -> 10513.2 | K35: =J35/365 -> 28.803288
G36: ДТ
A37: Sс уч к.д | B37: =B35*1.25 -> 0.66838986 | C37: га | F37: NO2 | G37: Б | H37: =B13*J12 -> 123750 | I37: =B19*J25*24*365 -> 2452.8 | J37: =SUM(H37:I37) -> 126202.8 | K37: =J37/365 -> 345.7611
G38: ДТ
A39: Mc | B39: 12 | F39: Pb | G39: Б | H39: =B13*K12 -> 4331.25 | I39: =B19*M25*24*365 -> 306.6 | J39: =SUM(H39:I39) -> 4637.85 | K39: =J39/365 -> 12.706438
A40: Mo | B40: 16 | G40: ДТ
A41: Мсо | B41: =B39+B40 -> 28 | F41: SO3 | G41: Б | H41: =B13*N25 -> 0 | I41: =B19*N25 -> 0 | J41: =SUM(H41:I41) -> 0 | K41: =J41/365 -> 0
A42: Мсо2 | B42: =B39+2*B40 -> 44 | G42: ДТ
...

Sheet Лист3
A1: Вещество | B1: m (т) | C1: ПДКсс | D1: А = 1 / ПДК | E1: f | F1: mfA
A2: СО | B2: =Лист2!J33/1000000 -> 2.6175105 | C2: =Лист2!J71 -> 3 | D2: =1/C2 -> 0.33333333 | E2: 0.5 | F2: =B2*E2*D2 -> 0.43625175
A3: SO2 | B3: =Лист2!J35/1000000 -> 0.0105132 | C3: =Лист2!J78 -> 0.05 | D3: =1/C3 -> 20 | E3: 1 | F3: =B3*E3*D3 -> 0.210264
A4: NO2 | B4: =Лист2!J37/1000000 -> 0.1262028 | C4: =Лист2!J68 -> 0.04 | D4: =1/C4 -> 25 | E4: 1 | F4: =B4*E4*D4 -> 3.15507
A5: Pd | B5: =Лист2!J39/1000000 -> 0.00463785 | C5: =Лист2!J70 -> 0.0003 | D5: =1/C5 -> 3333.3333 | E5: 4 | F5: =B5*E5*D5 -> 61.838
A6: SO3 | B6: =Лист2!J41 -> 0 | C6: =Лист2!J84 -> 0.15 | D6: =1/C6 -> 6.6666667 | E6: 0.5 | F6: =B6*E6*D6 -> 0
A7: CnHn | B7: =Лист2!J43/1000000 -> 0.230523 | C7: =Лист2!J74 -> 0.005 | D7: =1/C7 -> 200 | E7: 2.5 | F7: =B7*E7*D7 -> 115.2615
A8: Сажа | B8: =Лист2!J45/1000000 -> 0.012375 | C8: =Лист2!J69 -> 0.05 | D8: =1/C8 -> 20 | E8: 2.5 | F8: =B8*E8*D8 -> 0.61875
A9: NO | B9: =Лист2!J47/1000000 -> 0.00037668 | C9: =Лист2!J85 -> 0.06 | D9: =1/C9 -> 16.666667 | E9: 1 | F9: =B9*E9*D9 -> 0.006278
A10: С20Н12 | B10: =Лист2!J49/1000000 -> 1.5768e-09 | C10: =Лист2!J81 -> 1e-06 | D10: =1/C10 -> 1000000 | E10: 2.5 | F10: =B10*E10*D10 -> 0.003942
A11: fM | F11: =SUM(F2:F10) -> 181.53006
A13: γ | B13: 2.4 | C13: руб/усл.т.
A14: σ | B14: 1.68
A15: Уатм | B15: =B13*B14*F11 -> 731.92918 | C15: руб/год | E15: Вывод | F15: Ущерб от загрязнения атмосферы
