Workbook

Sheet Таблица 1.2
A1: Функция (реализация) | B1: Потоков | C1: Время, мс, | D1: Sp(n) | E1: Ep(n) | F1: Cp(n)
A2: НД 100000
A3: Заполнение массивов (посл.) | B3: 1 | C3: 9
A4: Заполнение массивов (парал. FOR) | B4: 2 | C4: 5 | D4: =$C$3/C4 -> 1.8 | E4: =D4/B4 -> 0.9 | F4: =B4*C4 -> 10
B5: 3 | C5: 3.1554 | D5: =$C$3/C5 -> 2.8522533 | E5: =D5/B5 -> 0.95075109 | F5: =B5*C5 -> 9.4662
B6: 4 | C6: 3 | D6: =$C$3/C6 -> 3 | E6: =D6/B6 -> 0.75 | F6: =B6*C6 -> 12
A7: Сложение массивов (посл.) | C7: 0.24
A8: Сложение массивов (парал. FOR) | B8: 2 | C8: 0.1567 | D8: =$C$7/C8 -> 1.531589 | E8: =D8/B8 -> 0.76579451 | F8: =B8*C8 -> 0.3134
B9: 3 | C9: 0.14 | D9: =$C$7/C9 -> 1.7142857 | E9: =D9/B9 -> 0.57142857 | F9: =B9*C9 -> 0.42
B10: 4 | C10: 0.12 | D10: =$C$7/C10 -> 2 | E10: =D10/B10 -> 0.5 | F10: =B10*C10 -> 0.48
A11: Сложение массивов (парал. Sections) | B11: 2 | C11: 0.16 | D11: =$C$7/C11 -> 1.5 | E11: =D11/B11 -> 0.75 | F11: =B11*C11 -> 0.32
B12: 3 | C12: 0.14 | D12: =$C$7/C12 -> 1.7142857 | E12: =D12/B12 -> 0.57142857 | F12: =B12*C12 -> 0.42
B13: 4 | C13: 0.12 | D13: =$C$7/C13 -> 2 | E13: =D13/B13 -> 0.5 | F13: =B13*C13 -> 0.48
A14: Подсчет суммы элементов итогового массива (посл.) | B14: 1 | C14: 0.235518
A15: Подсчет суммы элементов итогового массива (парал. редуктор) | B15: 2 | C15: 0.157211 | D15: =$C$14/C15 -> 1.4981013 | E15: =D15/B15 -> 0.74905064 | F15: =B15*C15 -> 0.314422
B16: 3 | C16: 0.12 | D16: =$C$14/C16 -> 1.96265 | E16: =D16/B16 -> 0.65421667 | F16: =B16*C16 -> 0.36
B17: 4 | C17: 0.10936 | D17: =$C$14/C17 -> 2.1536028 | E17: =D17/B17 -> 0.53840069 | F17: =B17*C17 -> 0.43744
A18: Подсчет суммы элементов итогового массива (парал. критическая секция) | B18: 2 | C18: 0.16 | D18: =$C$14/C18 -> 1.4719875 | E18: =D18/B18 -> 0.73599375 | F18: =B18*C18 -> 0.32
B19: 3 | C19: 0.157374 | D19: =$C$14/C19 -> 1.4965496 | E19: =D19/B19 -> 0.49884987 | F19: =B19*C19 -> 0.472122
B20: 4 | C20: 0.14 | D20: =$C$14/C20 -> 1.6822714 | E20: =D20/B20 -> 0.42056786 | F20: =B20*C20 -> 0.56
A21: НД 170000
A22: Заполнение массивов (посл.) | B22: 1 | C22: 15
A23: Заполнение массивов (парал. FOR) | B23: 2 | C23: 7.61616 | D23: =$C$22/C23 -> 1.9694964 | E23: =D23/B23 -> 0.98474822 | F23: =B23*C23 -> 15.23232
B24: 3 | C24: 5.38461 | D24: =$C$22/C24 -> 2.7857171 | E24: =D24/B24 -> 0.92857236 | F24: =B24*C24 -> 16.15383
B25: 4 | C25: 4.28524 | D25: =$C$22/C25 -> 3.5003874 | E25: =D25/B25 -> 0.87509684 | F25: =B25*C25 -> 17.14096
A26: Сложение массивов (посл.) | B26: 1 | C26: 0.430712
A27: Сложение массивов (парал. FOR) | B27: 2 | C27: 0.249933 | D27: =$C$26/C27 -> 1.7233098 | E27: =D27/B27 -> 0.86165492 | F27: =B27*C27 -> 0.499866
B28: 3 | C28: 0.2 | D28: =$C$26/C28 -> 2.15356 | E28: =D28/B28 -> 0.71785333 | F28: =B28*C28 -> 0.6
B29: 4 | C29: 0.164106 | D29: =$C$26/C29 -> 2.6245963 | E29: =D29/B29 -> 0.65614907 | F29: =B29*C29 -> 0.656424
A30: Сложение массивов (парал. Sections) | B30: 2 | C30: 0.265369 | D30: =$C$26/C30 -> 1.6230683 | E30: =D30/B30 -> 0.81153413 | F30: =B30*C30 -> 0.530738
B31: 3 | C31: 0.20443 | D31: =$C$26/C31 -> 2.1068923 | E31: =D31/B31 -> 0.70229744 | F31: =B31*C31 -> 0.61329
B32: 4 | C32: 0.172593 | D32: =$C$26/C32 -> 2.4955357 | E32: =D32/B32 -> 0.62388394 | F32: =B32*C32 -> 0.690372
A33: Подсчет суммы элементов итогового массива (посл.) | B33: 1 | C33: 0.4
A34: Подсчет суммы элементов итогового массива (парал. редуктор) | B34: 2 | C34: 0.241757 | D34: =$C$33/C34 -> 1.654554 | E34: =D34/B34 -> 0.82727698 | F34: =B34*C34 -> 0.483514
B35: 3 | C35: 0.194286 | D35: =$C$33/C35 -> 2.0588205 | E35: =D35/B35 -> 0.6862735 | F35: =B35*C35 -> 0.582858
B36: 4 | C36: 0.16136 | D36: =$C$33/C36 -> 2.4789291 | E36: =D36/B36 -> 0.61973228 | F36: =B36*C36 -> 0.64544
A37: Подсчет суммы элементов итогового массива (парал. критическая секция) | B37: 2 | C37: 0.248215 | D37: =$C$33/C37 -> 1.6115062 | E37: =D37/B37 -> 0.80575308 | F37: =B37*C37 -> 0.49643
B38: 3 | C38: 0.222222 | D38: =$C$33/C38 -> 1.8000018 | E38: =D38/B38 -> 0.6000006 | F38: =B38*C38 -> 0.666666
B39: 4 | C39: 0.198188 | D39: =$C$33/C39 -> 2.0182857 | E39: =D39/B39 -> 0.50457142 | F39: =B39*C39 -> 0.792752
A40: НД 240000
...

Sheet Таблица 1.3
A1: Потоков | B1: Функция (реализация) | C1: Время, мс, | D1: Sp(n) | E1: Ep(n) | F1: Cp(n)
A2: НД 100000
A3: 1 | B3: Комбинация (все последовательно) | C3: ='Таблица 1.2'!C3+'Таблица 1.2'!C7+'Таблица 1.2'!C14 -> 9.475518
A4: 2 | B4: Лучшая комбинация 1: парал. FOR, парал. FOR, парал. Редуктор | C4: ='Таблица 1.2'!C4+'Таблица 1.2'!C8+'Таблица 1.2'!C15 -> 5.313911 | D4: =$C$3/C4 -> 1.7831533 | E4: =D4/$A$4 -> 0.89157666 | F4: =C4*$A$4 -> 10.627822
B5: Лучшая комбинация 2: парал. FOR, парал. Sections, парал. Редуктор | C5: ='Таблица 1.2'!C4+'Таблица 1.2'!C11+'Таблица 1.2'!C15 -> 5.317211 | D5: =$C$3/C5 -> 1.7820466 | E5: =D5/$A$4 -> 0.89102332 | F5: =C5*$A$4 -> 10.634422
B6: Худшая комбинация: посл., посл., посл. | C6: ='Таблица 1.2'!C3+'Таблица 1.2'!C7+'Таблица 1.2'!C14 -> 9.475518 | D6: =$C$3/C6 -> 1 | E6: =D6/$A$4 -> 0.5 | F6: =C6*$A$4 -> 18.951036
A7: 3 | B7: Лучшая комбинация 1: парал. FOR, парал. FOR, парал. Редуктор | C7: ='Таблица 1.2'!C5+'Таблица 1.2'!C9+'Таблица 1.2'!C16 -> 3.4154 | D7: =$C$3/C7 -> 2.7743509 | E7: =D7/$A$7 -> 0.92478363 | F7: =C7*$A$7 -> 10.2462
B8: Лучшая комбинация 2: парал. FOR, парал. FOR, парал. Крит. секция | C8: ='Таблица 1.2'!C5+'Таблица 1.2'!C9+'Таблица 1.2'!C19 -> 3.452774 | D8: =$C$3/C8 -> 2.7443204 | E8: =D8/$A$7 -> 0.91477345 | F8: =C8*$A$7 -> 10.358322
B9: Худшая комбинация: посл., посл., посл. | C9: ='Таблица 1.2'!C3+'Таблица 1.2'!C7+'Таблица 1.2'!C14 -> 9.475518 | D9: =$C$3/C9 -> 1 | E9: =D9/$A$7 -> 0.33333333 | F9: =C9*$A$7 -> 28.426554
A10: 4 | B10: Лучшая комбинация 1: парал. FOR, парал. FOR, парал. Редуктор | C10: ='Таблица 1.2'!C6+'Таблица 1.2'!C10+'Таблица 1.2'!C17 -> 3.22936 | D10: =$C$3/C10 -> 2.9341783 | E10: =D10/$A$10 -> 0.73354457 | F10: =C10*$A$10 -> 12.91744
B11: Лучшая комбинация 2: парал. FOR, парал. Sections, парал. Редуктор | C11: ='Таблица 1.2'!C6+'Таблица 1.2'!C13+'Таблица 1.2'!C17 -> 3.22936 | D11: =$C$3/C11 -> 2.9341783 | E11: =D11/$A$10 -> 0.73354457 | F11: =C11*$A$10 -> 12.91744
B12: Худшая комбинация: посл., посл., посл. | C12: ='Таблица 1.2'!C3+'Таблица 1.2'!C7+'Таблица 1.2'!C14 -> 9.475518 | D12: =$C$3/C12 -> 1 | E12: =D12/$A$10 -> 0.25 | F12: =C12*$A$10 -> 37.902072
A13: НД 170000
A14: 1 | B14: Комбинация (все последовательно) | C14: ='Таблица 1.2'!C22+'Таблица 1.2'!C26+'Таблица 1.2'!C33 -> 15.830712
A15: 2 | B15: Лучшая комбинация 1: парал. FOR, парал. FOR, парал. Редуктор | C15: ='Таблица 1.2'!C23+'Таблица 1.2'!C27+'Таблица 1.2'!C34 -> 8.10785 | D15: =$C$14/C15 -> 1.9525166 | E15: =D15/$A$15 -> 0.97625832 | F15: =C15*$A$15 -> 16.2157
B16: Лучшая комбинация 2: парал. FOR, парал. Sections, парал. Редуктор | C16: ='Таблица 1.2'!C23+'Таблица 1.2'!C30+'Таблица 1.2'!C34 -> 8.123286 | D16: =$C$14/C16 -> 1.9488064 | E16: =D16/$A$15 -> 0.97440322 | F16: =C16*$A$15 -> 16.246572
B17: Худшая комбинация: посл., посл., посл. | C17: ='Таблица 1.2'!C22+'Таблица 1.2'!C26+'Таблица 1.2'!C33 -> 15.830712 | D17: =$C$14/C17 -> 1 | E17: =D17/$A$15 -> 0.5 | F17: =C17*$A$15 -> 31.661424
A18: 3 | B18: Лучшая комбинация 1: парал. FOR, парал. FOR, парал. Редуктор | C18: ='Таблица 1.2'!C24+'Таблица 1.2'!C28+'Таблица 1.2'!C35 -> 5.778896 | D18: =$C$14/C18 -> 2.7394007 | E18: =D18/$A$18 -> 0.91313358 | F18: =C18*$A$18 -> 17.336688
B19: Лучшая комбинация 2: парал. FOR, парал. Sections, парал. Редуктор | C19: ='Таблица 1.2'!C24+'Таблица 1.2'!C31+'Таблица 1.2'!C35 -> 5.783326 | D19: =$C$14/C19 -> 2.7373024 | E19: =D19/$A$18 -> 0.91243413 | F19: =C19*$A$18 -> 17.349978
B20: Худшая комбинация: посл., посл., посл. | C20: ='Таблица 1.2'!C22+'Таблица 1.2'!C26+'Таблица 1.2'!C33 -> 15.830712 | D20: =$C$14/C20 -> 1 | E20: =D20/$A$18 -> 0.33333333 | F20: =C20*$A$18 -> 47.492136
A21: 4 | B21: Лучшая комбинация 1: парал. FOR, парал. FOR, парал. Редуктор | C21: ='Таблица 1.2'!C25+'Таблица 1.2'!C29+'Таблица 1.2'!C36 -> 4.610706 | D21: =$C$14/C21 -> 3.4334681 | E21: =D21/$A$21 -> 0.85836703 | F21: =C21*$A$21 -> 18.442824
B22: Лучшая комбинация 2: парал. FOR, парал. Sections, парал. Редуктор | C22: ='Таблица 1.2'!C25+'Таблица 1.2'!C32+'Таблица 1.2'!C36 -> 4.619193 | D22: =$C$14/C22 -> 3.4271597 | E22: =D22/$A$21 -> 0.85678992 | F22: =C22*$A$21 -> 18.476772
B23: Худшая комбинация: посл., посл., посл. | C23: ='Таблица 1.2'!C22+'Таблица 1.2'!C26+'Таблица 1.2'!C33 -> 15.830712 | D23: =$C$14/C23 -> 1 | E23: =D23/$A$21 -> 0.25 | F23: =C23*$A$21 -> 63.322848
A24: НД 240000
A25: 1 | B25: Комбинация (все последовательно) | C25: ='Таблица 1.2'!C41+'Таблица 1.2'!C45+'Таблица 1.2'!C52 -> 22.169647
A26: 2 | B26: Лучшая комбинация 1: парал. FOR, парал. FOR, парал. Редуктор | C26: ='Таблица 1.2'!C42+'Таблица 1.2'!C46+'Таблица 1.2'!C53 -> 11.289601 | D26: =$C$25/C26 -> 1.9637228 | E26: =D26/$A$26 -> 0.98186141 | F26: =C26*$A$26 -> 22.579202
B27: Лучшая комбинация 2: парал. FOR, парал. FOR, парал. Крит. секция | C27: ='Таблица 1.2'!C42+'Таблица 1.2'!C46+'Таблица 1.2'!C56 -> 11.298355 | D27: =$C$25/C27 -> 1.9622013 | E27: =D27/$A$26 -> 0.98110066 | F27: =C27*$A$26 -> 22.59671
B28: Худшая комбинация: посл., посл., посл. | C28: ='Таблица 1.2'!C41+'Таблица 1.2'!C45+'Таблица 1.2'!C52 -> 22.169647 | D28: =$C$25/C28 -> 1 | E28: =D28/$A$26 -> 0.5 | F28: =C28*$A$26 -> 44.339294
A29: 3 | B29: Лучшая комбинация 1: парал. FOR, парал. FOR, парал. Редуктор | C29: ='Таблица 1.2'!C43+'Таблица 1.2'!C47+'Таблица 1.2'!C54 -> 7.892865 | D29: =$C$25/C29 -> 2.8088213 | E29: =D29/$A$29 -> 0.93627375 | F29: =C29*$A$29 -> 23.678595
B30: Лучшая комбинация 2: парал. FOR, парал. FOR, парал. Крит. секция | C30: ='Таблица 1.2'!C43+'Таблица 1.2'!C47+'Таблица 1.2'!C57 -> 7.909909 | D30: =$C$25/C30 -> 2.8027689 | E30: =D30/$A$29 -> 0.9342563 | F30: =C30*$A$29 -> 23.729727
B31: Худшая комбинация: посл., посл., посл. | C31: ='Таблица 1.2'!C41+'Таблица 1.2'!C45+'Таблица 1.2'!C52 -> 22.169647 | D31: =$C$25/C31 -> 1 | E31: =D31/$A$29 -> 0.33333333 | F31: =C31*$A$29 -> 66.508941
A32: 4 | B32: Лучшая комбинация 1: парал. FOR, парал. Sections, парал. Редуктор | C32: ='Таблица 1.2'!C44+'Таблица 1.2'!C48+'Таблица 1.2'!C55 -> 6.444384 | D32: =$C$25/C32 -> 3.4401499 | E32: =D32/$A$32 -> 0.86003748 | F32: =C32*$A$32 -> 25.777536
B33: Лучшая комбинация 2: парал. FOR, парал. FOR, парал. Редуктор | C33: ='Таблица 1.2'!C44+'Таблица 1.2'!C51+'Таблица 1.2'!C55 -> 6.453605 | D33: =$C$25/C33 -> 3.4352346 | E33: =D33/$A$32 -> 0.85880864 | F33: =C33*$A$32 -> 25.81442
B34: Худшая комбинация: посл., посл., посл. | C34: ='Таблица 1.2'!C41+'Таблица 1.2'!C45+'Таблица 1.2'!C52 -> 22.169647 | D34: =$C$25/C34 -> 1 | E34: =D34/$A$32 -> 0.25 | F34: =C34*$A$32 -> 88.678588
A35: НД 310000
A36: 1 | B36: Комбинация (все последовательно) | C36: ='Таблица 1.2'!C60+'Таблица 1.2'!C64+'Таблица 1.2'!C71 -> 28.272818
A37: 2 | B37: Лучшая комбинация 1: парал. FOR, парал. FOR, парал. Редуктор | C37: ='Таблица 1.2'!C61+'Таблица 1.2'!C65+'Таблица 1.2'!C72 -> 14.535807 | D37: =$C$36/C37 -> 1.9450463 | E37: =D37/$A$37 -> 0.97252316 | F37: =C37*$A$37 -> 29.071614
B38: Лучшая комбинация 2: парал. FOR, парал. FOR, парал. Крит. секция | C38: ='Таблица 1.2'!C61+'Таблица 1.2'!C65+'Таблица 1.2'!C75 -> 14.545289 | D38: =$C$36/C38 -> 1.9437784 | E38: =D38/$A$37 -> 0.97188918 | F38: =C38*$A$37 -> 29.090578
B39: Худшая комбинация: посл., посл., посл. | C39: ='Таблица 1.2'!C60+'Таблица 1.2'!C64+'Таблица 1.2'!C71 -> 28.272818 | D39: =$C$36/C39 -> 1 | E39: =D39/$A$37 -> 0.5 | F39: =C39*$A$37 -> 56.545636
A40: 3 | B40: Лучшая комбинация 1: парал. FOR, парал. Sections, парал. Редуктор | C40: ='Таблица 1.2'!C62+'Таблица 1.2'!C66+'Таблица 1.2'!C73 -> 10.007522 | D40: =$C$36/C40 -> 2.8251567 | E40: =D40/$A$40 -> 0.94171891 | F40: =C40*$A$40 -> 30.022566
...
